nohup: ignoring input
TensorFlow installation not found - running with reduced feature set.

NOTE: Using experimental fast data loading logic. To disable, pass
    "--load_fast=false" and report issues on GitHub. More details:
    https://github.com/tensorflow/tensorboard/issues/4784

TensorBoard 2.16.2 at http://386f0db0b08a:4000/ (Press CTRL+C to quit)
E0501 15:52:37.224859 139639671199296 _internal.py:96] Error on request:
Traceback (most recent call last):
  File "/workspace/env/lib/python3.10/site-packages/werkzeug/serving.py", line 362, in run_wsgi
    execute(self.server.app)
  File "/workspace/env/lib/python3.10/site-packages/werkzeug/serving.py", line 323, in execute
    application_iter = app(environ, start_response)
  File "/workspace/env/lib/python3.10/site-packages/tensorboard/backend/application.py", line 528, in __call__
    return self._app(environ, start_response)
  File "/workspace/env/lib/python3.10/site-packages/tensorboard/backend/application.py", line 569, in wrapper
    return wsgi_app(environ, start_response)
  File "/workspace/env/lib/python3.10/site-packages/tensorboard/backend/security_validator.py", line 91, in __call__
    return self._application(environ, start_response_proxy)
  File "/workspace/env/lib/python3.10/site-packages/tensorboard/backend/path_prefix.py", line 68, in __call__
    return self._application(environ, start_response)
  File "/workspace/env/lib/python3.10/site-packages/tensorboard/backend/experiment_id.py", line 73, in __call__
    return self._application(environ, start_response)
  File "/workspace/env/lib/python3.10/site-packages/tensorboard/backend/empty_path_redirect.py", line 43, in __call__
    return self._application(environ, start_response)
  File "/workspace/env/lib/python3.10/site-packages/tensorboard/backend/client_feature_flags.py", line 55, in __call__
    return self._application(environ, start_response)
  File "/workspace/env/lib/python3.10/site-packages/tensorboard/backend/auth_context_middleware.py", line 38, in __call__
    return self._application(environ, start_response)
  File "/workspace/env/lib/python3.10/site-packages/tensorboard/backend/application.py", line 551, in _route_request
    return self.exact_routes[clean_path](environ, start_response)
  File "/workspace/env/lib/python3.10/site-packages/werkzeug/wrappers/request.py", line 189, in application
    resp = f(*args[:-2] + (request,))
  File "/workspace/env/lib/python3.10/site-packages/tensorboard/plugins/hparams/hparams_plugin.py", line 121, in get_experiment_route
    json_format.MessageToJson(
TypeError: MessageToJson() got an unexpected keyword argument 'including_default_value_fields'
E0501 15:52:38.541891 139639671199296 _internal.py:96] Error on request:
Traceback (most recent call last):
  File "/workspace/env/lib/python3.10/site-packages/werkzeug/serving.py", line 362, in run_wsgi
    execute(self.server.app)
  File "/workspace/env/lib/python3.10/site-packages/werkzeug/serving.py", line 323, in execute
    application_iter = app(environ, start_response)
  File "/workspace/env/lib/python3.10/site-packages/tensorboard/backend/application.py", line 528, in __call__
    return self._app(environ, start_response)
  File "/workspace/env/lib/python3.10/site-packages/tensorboard/backend/application.py", line 569, in wrapper
    return wsgi_app(environ, start_response)
  File "/workspace/env/lib/python3.10/site-packages/tensorboard/backend/security_validator.py", line 91, in __call__
    return self._application(environ, start_response_proxy)
  File "/workspace/env/lib/python3.10/site-packages/tensorboard/backend/path_prefix.py", line 68, in __call__
    return self._application(environ, start_response)
  File "/workspace/env/lib/python3.10/site-packages/tensorboard/backend/experiment_id.py", line 73, in __call__
    return self._application(environ, start_response)
  File "/workspace/env/lib/python3.10/site-packages/tensorboard/backend/empty_path_redirect.py", line 43, in __call__
    return self._application(environ, start_response)
  File "/workspace/env/lib/python3.10/site-packages/tensorboard/backend/client_feature_flags.py", line 55, in __call__
    return self._application(environ, start_response)
  File "/workspace/env/lib/python3.10/site-packages/tensorboard/backend/auth_context_middleware.py", line 38, in __call__
    return self._application(environ, start_response)
  File "/workspace/env/lib/python3.10/site-packages/tensorboard/backend/application.py", line 551, in _route_request
    return self.exact_routes[clean_path](environ, start_response)
  File "/workspace/env/lib/python3.10/site-packages/werkzeug/wrappers/request.py", line 189, in application
    resp = f(*args[:-2] + (request,))
  File "/workspace/env/lib/python3.10/site-packages/tensorboard/plugins/hparams/hparams_plugin.py", line 121, in get_experiment_route
    json_format.MessageToJson(
TypeError: MessageToJson() got an unexpected keyword argument 'including_default_value_fields'
E0501 15:52:59.803052 139639671199296 _internal.py:96] Error on request:
Traceback (most recent call last):
  File "/workspace/env/lib/python3.10/site-packages/werkzeug/serving.py", line 362, in run_wsgi
    execute(self.server.app)
  File "/workspace/env/lib/python3.10/site-packages/werkzeug/serving.py", line 323, in execute
    application_iter = app(environ, start_response)
  File "/workspace/env/lib/python3.10/site-packages/tensorboard/backend/application.py", line 528, in __call__
    return self._app(environ, start_response)
  File "/workspace/env/lib/python3.10/site-packages/tensorboard/backend/application.py", line 569, in wrapper
    return wsgi_app(environ, start_response)
  File "/workspace/env/lib/python3.10/site-packages/tensorboard/backend/security_validator.py", line 91, in __call__
    return self._application(environ, start_response_proxy)
  File "/workspace/env/lib/python3.10/site-packages/tensorboard/backend/path_prefix.py", line 68, in __call__
    return self._application(environ, start_response)
  File "/workspace/env/lib/python3.10/site-packages/tensorboard/backend/experiment_id.py", line 73, in __call__
    return self._application(environ, start_response)
  File "/workspace/env/lib/python3.10/site-packages/tensorboard/backend/empty_path_redirect.py", line 43, in __call__
    return self._application(environ, start_response)
  File "/workspace/env/lib/python3.10/site-packages/tensorboard/backend/client_feature_flags.py", line 55, in __call__
    return self._application(environ, start_response)
  File "/workspace/env/lib/python3.10/site-packages/tensorboard/backend/auth_context_middleware.py", line 38, in __call__
    return self._application(environ, start_response)
  File "/workspace/env/lib/python3.10/site-packages/tensorboard/backend/application.py", line 551, in _route_request
    return self.exact_routes[clean_path](environ, start_response)
  File "/workspace/env/lib/python3.10/site-packages/werkzeug/wrappers/request.py", line 189, in application
    resp = f(*args[:-2] + (request,))
  File "/workspace/env/lib/python3.10/site-packages/tensorboard/plugins/hparams/hparams_plugin.py", line 121, in get_experiment_route
    json_format.MessageToJson(
TypeError: MessageToJson() got an unexpected keyword argument 'including_default_value_fields'
E0501 15:53:02.104204 139639671199296 _internal.py:96] Error on request:
Traceback (most recent call last):
  File "/workspace/env/lib/python3.10/site-packages/werkzeug/serving.py", line 362, in run_wsgi
    execute(self.server.app)
  File "/workspace/env/lib/python3.10/site-packages/werkzeug/serving.py", line 323, in execute
    application_iter = app(environ, start_response)
  File "/workspace/env/lib/python3.10/site-packages/tensorboard/backend/application.py", line 528, in __call__
    return self._app(environ, start_response)
  File "/workspace/env/lib/python3.10/site-packages/tensorboard/backend/application.py", line 569, in wrapper
    return wsgi_app(environ, start_response)
  File "/workspace/env/lib/python3.10/site-packages/tensorboard/backend/security_validator.py", line 91, in __call__
    return self._application(environ, start_response_proxy)
  File "/workspace/env/lib/python3.10/site-packages/tensorboard/backend/path_prefix.py", line 68, in __call__
    return self._application(environ, start_response)
  File "/workspace/env/lib/python3.10/site-packages/tensorboard/backend/experiment_id.py", line 73, in __call__
    return self._application(environ, start_response)
  File "/workspace/env/lib/python3.10/site-packages/tensorboard/backend/empty_path_redirect.py", line 43, in __call__
    return self._application(environ, start_response)
  File "/workspace/env/lib/python3.10/site-packages/tensorboard/backend/client_feature_flags.py", line 55, in __call__
    return self._application(environ, start_response)
  File "/workspace/env/lib/python3.10/site-packages/tensorboard/backend/auth_context_middleware.py", line 38, in __call__
    return self._application(environ, start_response)
  File "/workspace/env/lib/python3.10/site-packages/tensorboard/backend/application.py", line 551, in _route_request
    return self.exact_routes[clean_path](environ, start_response)
  File "/workspace/env/lib/python3.10/site-packages/werkzeug/wrappers/request.py", line 189, in application
    resp = f(*args[:-2] + (request,))
  File "/workspace/env/lib/python3.10/site-packages/tensorboard/plugins/hparams/hparams_plugin.py", line 121, in get_experiment_route
    json_format.MessageToJson(
TypeError: MessageToJson() got an unexpected keyword argument 'including_default_value_fields'
E0501 16:02:12.119955 139639176291904 _internal.py:96] Error on request:
Traceback (most recent call last):
  File "/workspace/env/lib/python3.10/site-packages/werkzeug/serving.py", line 362, in run_wsgi
    execute(self.server.app)
  File "/workspace/env/lib/python3.10/site-packages/werkzeug/serving.py", line 323, in execute
    application_iter = app(environ, start_response)
  File "/workspace/env/lib/python3.10/site-packages/tensorboard/backend/application.py", line 528, in __call__
    return self._app(environ, start_response)
  File "/workspace/env/lib/python3.10/site-packages/tensorboard/backend/application.py", line 569, in wrapper
    return wsgi_app(environ, start_response)
  File "/workspace/env/lib/python3.10/site-packages/tensorboard/backend/security_validator.py", line 91, in __call__
    return self._application(environ, start_response_proxy)
  File "/workspace/env/lib/python3.10/site-packages/tensorboard/backend/path_prefix.py", line 68, in __call__
    return self._application(environ, start_response)
  File "/workspace/env/lib/python3.10/site-packages/tensorboard/backend/experiment_id.py", line 73, in __call__
    return self._application(environ, start_response)
  File "/workspace/env/lib/python3.10/site-packages/tensorboard/backend/empty_path_redirect.py", line 43, in __call__
    return self._application(environ, start_response)
  File "/workspace/env/lib/python3.10/site-packages/tensorboard/backend/client_feature_flags.py", line 55, in __call__
    return self._application(environ, start_response)
  File "/workspace/env/lib/python3.10/site-packages/tensorboard/backend/auth_context_middleware.py", line 38, in __call__
    return self._application(environ, start_response)
  File "/workspace/env/lib/python3.10/site-packages/tensorboard/backend/application.py", line 551, in _route_request
    return self.exact_routes[clean_path](environ, start_response)
  File "/workspace/env/lib/python3.10/site-packages/werkzeug/wrappers/request.py", line 189, in application
    resp = f(*args[:-2] + (request,))
  File "/workspace/env/lib/python3.10/site-packages/tensorboard/plugins/hparams/hparams_plugin.py", line 121, in get_experiment_route
    json_format.MessageToJson(
TypeError: MessageToJson() got an unexpected keyword argument 'including_default_value_fields'
E0501 16:02:13.230992 139639176291904 _internal.py:96] Error on request:
Traceback (most recent call last):
  File "/workspace/env/lib/python3.10/site-packages/werkzeug/serving.py", line 362, in run_wsgi
    execute(self.server.app)
  File "/workspace/env/lib/python3.10/site-packages/werkzeug/serving.py", line 323, in execute
    application_iter = app(environ, start_response)
  File "/workspace/env/lib/python3.10/site-packages/tensorboard/backend/application.py", line 528, in __call__
    return self._app(environ, start_response)
  File "/workspace/env/lib/python3.10/site-packages/tensorboard/backend/application.py", line 569, in wrapper
    return wsgi_app(environ, start_response)
  File "/workspace/env/lib/python3.10/site-packages/tensorboard/backend/security_validator.py", line 91, in __call__
    return self._application(environ, start_response_proxy)
  File "/workspace/env/lib/python3.10/site-packages/tensorboard/backend/path_prefix.py", line 68, in __call__
    return self._application(environ, start_response)
  File "/workspace/env/lib/python3.10/site-packages/tensorboard/backend/experiment_id.py", line 73, in __call__
    return self._application(environ, start_response)
  File "/workspace/env/lib/python3.10/site-packages/tensorboard/backend/empty_path_redirect.py", line 43, in __call__
    return self._application(environ, start_response)
  File "/workspace/env/lib/python3.10/site-packages/tensorboard/backend/client_feature_flags.py", line 55, in __call__
    return self._application(environ, start_response)
  File "/workspace/env/lib/python3.10/site-packages/tensorboard/backend/auth_context_middleware.py", line 38, in __call__
    return self._application(environ, start_response)
  File "/workspace/env/lib/python3.10/site-packages/tensorboard/backend/application.py", line 551, in _route_request
    return self.exact_routes[clean_path](environ, start_response)
  File "/workspace/env/lib/python3.10/site-packages/werkzeug/wrappers/request.py", line 189, in application
    resp = f(*args[:-2] + (request,))
  File "/workspace/env/lib/python3.10/site-packages/tensorboard/plugins/hparams/hparams_plugin.py", line 121, in get_experiment_route
    json_format.MessageToJson(
TypeError: MessageToJson() got an unexpected keyword argument 'including_default_value_fields'
E0501 16:19:44.303493 139639184684608 _internal.py:96] Error on request:
Traceback (most recent call last):
  File "/workspace/env/lib/python3.10/site-packages/werkzeug/serving.py", line 362, in run_wsgi
    execute(self.server.app)
  File "/workspace/env/lib/python3.10/site-packages/werkzeug/serving.py", line 323, in execute
    application_iter = app(environ, start_response)
  File "/workspace/env/lib/python3.10/site-packages/tensorboard/backend/application.py", line 528, in __call__
    return self._app(environ, start_response)
  File "/workspace/env/lib/python3.10/site-packages/tensorboard/backend/application.py", line 569, in wrapper
    return wsgi_app(environ, start_response)
  File "/workspace/env/lib/python3.10/site-packages/tensorboard/backend/security_validator.py", line 91, in __call__
    return self._application(environ, start_response_proxy)
  File "/workspace/env/lib/python3.10/site-packages/tensorboard/backend/path_prefix.py", line 68, in __call__
    return self._application(environ, start_response)
  File "/workspace/env/lib/python3.10/site-packages/tensorboard/backend/experiment_id.py", line 73, in __call__
    return self._application(environ, start_response)
  File "/workspace/env/lib/python3.10/site-packages/tensorboard/backend/empty_path_redirect.py", line 43, in __call__
    return self._application(environ, start_response)
  File "/workspace/env/lib/python3.10/site-packages/tensorboard/backend/client_feature_flags.py", line 55, in __call__
    return self._application(environ, start_response)
  File "/workspace/env/lib/python3.10/site-packages/tensorboard/backend/auth_context_middleware.py", line 38, in __call__
    return self._application(environ, start_response)
  File "/workspace/env/lib/python3.10/site-packages/tensorboard/backend/application.py", line 551, in _route_request
    return self.exact_routes[clean_path](environ, start_response)
  File "/workspace/env/lib/python3.10/site-packages/werkzeug/wrappers/request.py", line 189, in application
    resp = f(*args[:-2] + (request,))
  File "/workspace/env/lib/python3.10/site-packages/tensorboard/plugins/hparams/hparams_plugin.py", line 121, in get_experiment_route
    json_format.MessageToJson(
TypeError: MessageToJson() got an unexpected keyword argument 'including_default_value_fields'
E0501 16:19:45.161262 139639176291904 _internal.py:96] Error on request:
Traceback (most recent call last):
  File "/workspace/env/lib/python3.10/site-packages/werkzeug/serving.py", line 362, in run_wsgi
    execute(self.server.app)
  File "/workspace/env/lib/python3.10/site-packages/werkzeug/serving.py", line 323, in execute
    application_iter = app(environ, start_response)
  File "/workspace/env/lib/python3.10/site-packages/tensorboard/backend/application.py", line 528, in __call__
    return self._app(environ, start_response)
  File "/workspace/env/lib/python3.10/site-packages/tensorboard/backend/application.py", line 569, in wrapper
    return wsgi_app(environ, start_response)
  File "/workspace/env/lib/python3.10/site-packages/tensorboard/backend/security_validator.py", line 91, in __call__
    return self._application(environ, start_response_proxy)
  File "/workspace/env/lib/python3.10/site-packages/tensorboard/backend/path_prefix.py", line 68, in __call__
    return self._application(environ, start_response)
  File "/workspace/env/lib/python3.10/site-packages/tensorboard/backend/experiment_id.py", line 73, in __call__
    return self._application(environ, start_response)
  File "/workspace/env/lib/python3.10/site-packages/tensorboard/backend/empty_path_redirect.py", line 43, in __call__
    return self._application(environ, start_response)
  File "/workspace/env/lib/python3.10/site-packages/tensorboard/backend/client_feature_flags.py", line 55, in __call__
    return self._application(environ, start_response)
  File "/workspace/env/lib/python3.10/site-packages/tensorboard/backend/auth_context_middleware.py", line 38, in __call__
    return self._application(environ, start_response)
  File "/workspace/env/lib/python3.10/site-packages/tensorboard/backend/application.py", line 551, in _route_request
    return self.exact_routes[clean_path](environ, start_response)
  File "/workspace/env/lib/python3.10/site-packages/werkzeug/wrappers/request.py", line 189, in application
    resp = f(*args[:-2] + (request,))
  File "/workspace/env/lib/python3.10/site-packages/tensorboard/plugins/hparams/hparams_plugin.py", line 121, in get_experiment_route
    json_format.MessageToJson(
TypeError: MessageToJson() got an unexpected keyword argument 'including_default_value_fields'
E0501 17:26:09.037361 139639176291904 _internal.py:96] Error on request:
Traceback (most recent call last):
  File "/workspace/env/lib/python3.10/site-packages/werkzeug/serving.py", line 362, in run_wsgi
    execute(self.server.app)
  File "/workspace/env/lib/python3.10/site-packages/werkzeug/serving.py", line 323, in execute
    application_iter = app(environ, start_response)
  File "/workspace/env/lib/python3.10/site-packages/tensorboard/backend/application.py", line 528, in __call__
    return self._app(environ, start_response)
  File "/workspace/env/lib/python3.10/site-packages/tensorboard/backend/application.py", line 569, in wrapper
    return wsgi_app(environ, start_response)
  File "/workspace/env/lib/python3.10/site-packages/tensorboard/backend/security_validator.py", line 91, in __call__
    return self._application(environ, start_response_proxy)
  File "/workspace/env/lib/python3.10/site-packages/tensorboard/backend/path_prefix.py", line 68, in __call__
    return self._application(environ, start_response)
  File "/workspace/env/lib/python3.10/site-packages/tensorboard/backend/experiment_id.py", line 73, in __call__
    return self._application(environ, start_response)
  File "/workspace/env/lib/python3.10/site-packages/tensorboard/backend/empty_path_redirect.py", line 43, in __call__
    return self._application(environ, start_response)
  File "/workspace/env/lib/python3.10/site-packages/tensorboard/backend/client_feature_flags.py", line 55, in __call__
    return self._application(environ, start_response)
  File "/workspace/env/lib/python3.10/site-packages/tensorboard/backend/auth_context_middleware.py", line 38, in __call__
    return self._application(environ, start_response)
  File "/workspace/env/lib/python3.10/site-packages/tensorboard/backend/application.py", line 551, in _route_request
    return self.exact_routes[clean_path](environ, start_response)
  File "/workspace/env/lib/python3.10/site-packages/werkzeug/wrappers/request.py", line 189, in application
    resp = f(*args[:-2] + (request,))
  File "/workspace/env/lib/python3.10/site-packages/tensorboard/plugins/hparams/hparams_plugin.py", line 121, in get_experiment_route
    json_format.MessageToJson(
TypeError: MessageToJson() got an unexpected keyword argument 'including_default_value_fields'
E0501 17:26:10.213474 139639176291904 _internal.py:96] Error on request:
Traceback (most recent call last):
  File "/workspace/env/lib/python3.10/site-packages/werkzeug/serving.py", line 362, in run_wsgi
    execute(self.server.app)
  File "/workspace/env/lib/python3.10/site-packages/werkzeug/serving.py", line 323, in execute
    application_iter = app(environ, start_response)
  File "/workspace/env/lib/python3.10/site-packages/tensorboard/backend/application.py", line 528, in __call__
    return self._app(environ, start_response)
  File "/workspace/env/lib/python3.10/site-packages/tensorboard/backend/application.py", line 569, in wrapper
    return wsgi_app(environ, start_response)
  File "/workspace/env/lib/python3.10/site-packages/tensorboard/backend/security_validator.py", line 91, in __call__
    return self._application(environ, start_response_proxy)
  File "/workspace/env/lib/python3.10/site-packages/tensorboard/backend/path_prefix.py", line 68, in __call__
    return self._application(environ, start_response)
  File "/workspace/env/lib/python3.10/site-packages/tensorboard/backend/experiment_id.py", line 73, in __call__
    return self._application(environ, start_response)
  File "/workspace/env/lib/python3.10/site-packages/tensorboard/backend/empty_path_redirect.py", line 43, in __call__
    return self._application(environ, start_response)
  File "/workspace/env/lib/python3.10/site-packages/tensorboard/backend/client_feature_flags.py", line 55, in __call__
    return self._application(environ, start_response)
  File "/workspace/env/lib/python3.10/site-packages/tensorboard/backend/auth_context_middleware.py", line 38, in __call__
    return self._application(environ, start_response)
  File "/workspace/env/lib/python3.10/site-packages/tensorboard/backend/application.py", line 551, in _route_request
    return self.exact_routes[clean_path](environ, start_response)
  File "/workspace/env/lib/python3.10/site-packages/werkzeug/wrappers/request.py", line 189, in application
    resp = f(*args[:-2] + (request,))
  File "/workspace/env/lib/python3.10/site-packages/tensorboard/plugins/hparams/hparams_plugin.py", line 121, in get_experiment_route
    json_format.MessageToJson(
TypeError: MessageToJson() got an unexpected keyword argument 'including_default_value_fields'
E0502 04:19:20.510308 139639671199296 _internal.py:96] Error on request:
Traceback (most recent call last):
  File "/workspace/env/lib/python3.10/site-packages/werkzeug/serving.py", line 362, in run_wsgi
    execute(self.server.app)
  File "/workspace/env/lib/python3.10/site-packages/werkzeug/serving.py", line 323, in execute
    application_iter = app(environ, start_response)
  File "/workspace/env/lib/python3.10/site-packages/tensorboard/backend/application.py", line 528, in __call__
    return self._app(environ, start_response)
  File "/workspace/env/lib/python3.10/site-packages/tensorboard/backend/application.py", line 569, in wrapper
    return wsgi_app(environ, start_response)
  File "/workspace/env/lib/python3.10/site-packages/tensorboard/backend/security_validator.py", line 91, in __call__
    return self._application(environ, start_response_proxy)
  File "/workspace/env/lib/python3.10/site-packages/tensorboard/backend/path_prefix.py", line 68, in __call__
    return self._application(environ, start_response)
  File "/workspace/env/lib/python3.10/site-packages/tensorboard/backend/experiment_id.py", line 73, in __call__
    return self._application(environ, start_response)
  File "/workspace/env/lib/python3.10/site-packages/tensorboard/backend/empty_path_redirect.py", line 43, in __call__
    return self._application(environ, start_response)
  File "/workspace/env/lib/python3.10/site-packages/tensorboard/backend/client_feature_flags.py", line 55, in __call__
    return self._application(environ, start_response)
  File "/workspace/env/lib/python3.10/site-packages/tensorboard/backend/auth_context_middleware.py", line 38, in __call__
    return self._application(environ, start_response)
  File "/workspace/env/lib/python3.10/site-packages/tensorboard/backend/application.py", line 551, in _route_request
    return self.exact_routes[clean_path](environ, start_response)
  File "/workspace/env/lib/python3.10/site-packages/werkzeug/wrappers/request.py", line 189, in application
    resp = f(*args[:-2] + (request,))
  File "/workspace/env/lib/python3.10/site-packages/tensorboard/plugins/hparams/hparams_plugin.py", line 121, in get_experiment_route
    json_format.MessageToJson(
TypeError: MessageToJson() got an unexpected keyword argument 'including_default_value_fields'
E0502 04:19:21.931002 139639679592000 _internal.py:96] Error on request:
Traceback (most recent call last):
  File "/workspace/env/lib/python3.10/site-packages/werkzeug/serving.py", line 362, in run_wsgi
    execute(self.server.app)
  File "/workspace/env/lib/python3.10/site-packages/werkzeug/serving.py", line 323, in execute
    application_iter = app(environ, start_response)
  File "/workspace/env/lib/python3.10/site-packages/tensorboard/backend/application.py", line 528, in __call__
    return self._app(environ, start_response)
  File "/workspace/env/lib/python3.10/site-packages/tensorboard/backend/application.py", line 569, in wrapper
    return wsgi_app(environ, start_response)
  File "/workspace/env/lib/python3.10/site-packages/tensorboard/backend/security_validator.py", line 91, in __call__
    return self._application(environ, start_response_proxy)
  File "/workspace/env/lib/python3.10/site-packages/tensorboard/backend/path_prefix.py", line 68, in __call__
    return self._application(environ, start_response)
  File "/workspace/env/lib/python3.10/site-packages/tensorboard/backend/experiment_id.py", line 73, in __call__
    return self._application(environ, start_response)
  File "/workspace/env/lib/python3.10/site-packages/tensorboard/backend/empty_path_redirect.py", line 43, in __call__
    return self._application(environ, start_response)
  File "/workspace/env/lib/python3.10/site-packages/tensorboard/backend/client_feature_flags.py", line 55, in __call__
    return self._application(environ, start_response)
  File "/workspace/env/lib/python3.10/site-packages/tensorboard/backend/auth_context_middleware.py", line 38, in __call__
    return self._application(environ, start_response)
  File "/workspace/env/lib/python3.10/site-packages/tensorboard/backend/application.py", line 551, in _route_request
    return self.exact_routes[clean_path](environ, start_response)
  File "/workspace/env/lib/python3.10/site-packages/werkzeug/wrappers/request.py", line 189, in application
    resp = f(*args[:-2] + (request,))
  File "/workspace/env/lib/python3.10/site-packages/tensorboard/plugins/hparams/hparams_plugin.py", line 121, in get_experiment_route
    json_format.MessageToJson(
TypeError: MessageToJson() got an unexpected keyword argument 'including_default_value_fields'
E0502 04:20:14.822436 139639184684608 _internal.py:96] Error on request:
Traceback (most recent call last):
  File "/workspace/env/lib/python3.10/site-packages/werkzeug/serving.py", line 362, in run_wsgi
    execute(self.server.app)
  File "/workspace/env/lib/python3.10/site-packages/werkzeug/serving.py", line 323, in execute
    application_iter = app(environ, start_response)
  File "/workspace/env/lib/python3.10/site-packages/tensorboard/backend/application.py", line 528, in __call__
    return self._app(environ, start_response)
  File "/workspace/env/lib/python3.10/site-packages/tensorboard/backend/application.py", line 569, in wrapper
    return wsgi_app(environ, start_response)
  File "/workspace/env/lib/python3.10/site-packages/tensorboard/backend/security_validator.py", line 91, in __call__
    return self._application(environ, start_response_proxy)
  File "/workspace/env/lib/python3.10/site-packages/tensorboard/backend/path_prefix.py", line 68, in __call__
    return self._application(environ, start_response)
  File "/workspace/env/lib/python3.10/site-packages/tensorboard/backend/experiment_id.py", line 73, in __call__
    return self._application(environ, start_response)
  File "/workspace/env/lib/python3.10/site-packages/tensorboard/backend/empty_path_redirect.py", line 43, in __call__
    return self._application(environ, start_response)
  File "/workspace/env/lib/python3.10/site-packages/tensorboard/backend/client_feature_flags.py", line 55, in __call__
    return self._application(environ, start_response)
  File "/workspace/env/lib/python3.10/site-packages/tensorboard/backend/auth_context_middleware.py", line 38, in __call__
    return self._application(environ, start_response)
  File "/workspace/env/lib/python3.10/site-packages/tensorboard/backend/application.py", line 551, in _route_request
    return self.exact_routes[clean_path](environ, start_response)
  File "/workspace/env/lib/python3.10/site-packages/werkzeug/wrappers/request.py", line 189, in application
    resp = f(*args[:-2] + (request,))
  File "/workspace/env/lib/python3.10/site-packages/tensorboard/plugins/hparams/hparams_plugin.py", line 121, in get_experiment_route
    json_format.MessageToJson(
TypeError: MessageToJson() got an unexpected keyword argument 'including_default_value_fields'
E0502 04:20:15.742448 139639184684608 _internal.py:96] Error on request:
Traceback (most recent call last):
  File "/workspace/env/lib/python3.10/site-packages/werkzeug/serving.py", line 362, in run_wsgi
    execute(self.server.app)
  File "/workspace/env/lib/python3.10/site-packages/werkzeug/serving.py", line 323, in execute
    application_iter = app(environ, start_response)
  File "/workspace/env/lib/python3.10/site-packages/tensorboard/backend/application.py", line 528, in __call__
    return self._app(environ, start_response)
  File "/workspace/env/lib/python3.10/site-packages/tensorboard/backend/application.py", line 569, in wrapper
    return wsgi_app(environ, start_response)
  File "/workspace/env/lib/python3.10/site-packages/tensorboard/backend/security_validator.py", line 91, in __call__
    return self._application(environ, start_response_proxy)
  File "/workspace/env/lib/python3.10/site-packages/tensorboard/backend/path_prefix.py", line 68, in __call__
    return self._application(environ, start_response)
  File "/workspace/env/lib/python3.10/site-packages/tensorboard/backend/experiment_id.py", line 73, in __call__
    return self._application(environ, start_response)
  File "/workspace/env/lib/python3.10/site-packages/tensorboard/backend/empty_path_redirect.py", line 43, in __call__
    return self._application(environ, start_response)
  File "/workspace/env/lib/python3.10/site-packages/tensorboard/backend/client_feature_flags.py", line 55, in __call__
    return self._application(environ, start_response)
  File "/workspace/env/lib/python3.10/site-packages/tensorboard/backend/auth_context_middleware.py", line 38, in __call__
    return self._application(environ, start_response)
  File "/workspace/env/lib/python3.10/site-packages/tensorboard/backend/application.py", line 551, in _route_request
    return self.exact_routes[clean_path](environ, start_response)
  File "/workspace/env/lib/python3.10/site-packages/werkzeug/wrappers/request.py", line 189, in application
    resp = f(*args[:-2] + (request,))
  File "/workspace/env/lib/python3.10/site-packages/tensorboard/plugins/hparams/hparams_plugin.py", line 121, in get_experiment_route
    json_format.MessageToJson(
TypeError: MessageToJson() got an unexpected keyword argument 'including_default_value_fields'
